<?xml version="1.0" ?>
<!-- pi 3.14159265359 1.57079632679-->
<robot name="mck">
  <link name="world">
  </link>
  <joint name="fixed" type="fixed">
    <origin rpy="0 0 0" xyz="0 0 0.0 "/>
    <parent link="world"/>
    <child link="base_link"/>
  </joint>

  <link name="base_link">
    <visual>
        <geometry>
            <box size="0.2 0.2 0.2"/>
        </geometry>
    </visual>
    <collision>
        <geometry>
            <box size="0.2 0.2 0.2"/>
        </geometry>
    </collision>
    <inertial>
        <mass value="1"/>
        <inertia ixx="0.1" ixy="0.0" ixz="0.0" iyy="0.1" iyz="0.0" izz="0.1"/>
    </inertial>
  </link>

  <joint name="first_spring_damper" type="prismatic">
    <origin rpy="0 0 0" xyz="0.5 0 0"/>
    <axis xyz="1 0 0"/>
    <parent link="base_link"/>
    <child link="link_1"/>
    <dynamics damping="0.5"/>
    <limit effort="10000" lower="-10.0" upper="10.0" velocity="5.0"/>
  </joint>

    <link name="link_1">
        <visual>
            <geometry>
                <box size="0.2 0.2 0.2"/>
            </geometry>
        </visual>
        <collision>
            <geometry>
                <box size="0.2 0.2 0.2"/>
            </geometry>
        </collision>
        <inertial>
            <mass value="1"/>
            <inertia ixx="0.1" ixy="0.0" ixz="0.0" iyy="0.1" iyz="0.0" izz="0.1"/>
        </inertial>
    </link>
</robot>