<sdf version='1.7'>
  <model name='crankrobot'>
    <joint name='world2base' type='fixed'>
      <pose relative_to='__model__'>0 0 0.1 0 -0 0</pose>
      <parent>world</parent>
      <child>base</child>
    </joint>
    <link name='base'>
      <pose relative_to='world2base'>0 0 0 0 -0 0</pose>
      <inertial>
        <pose>0 0 0.05 0 -0 0</pose>
        <mass>5</mass>
        <inertia>
          <ixx>1</ixx>
          <ixy>0</ixy>
          <ixz>0</ixz>
          <iyy>1</iyy>
          <iyz>0</iyz>
          <izz>1</izz>
        </inertia>
      </inertial>
      <collision name='base_collision'>
        <pose>0 0 0.05 0 -0 0</pose>
        <geometry>
          <box>
            <size>0.25 0.25 0.25</size>
          </box>
        </geometry>
      </collision>
      <visual name='base_visual'>
        <pose>0 0 0 0 -0 0</pose>
        <geometry>
          <box>
            <size>0.25 0.25 0.25</size>
          </box>
        </geometry>
      </visual>
    </link>

    <joint name='joint1' type='revolute'>
      <pose relative_to='base'>0 0 0.1 0.5 -0 0</pose>
      <parent>base</parent>
      <child>link_1</child>
      <axis>
        <xyz>1 0 0</xyz>
      </axis>
    </joint>
    <link name='link_1'>
      <pose relative_to='joint1'>0 0 0 0 -0 0</pose>
      <inertial>
        <pose>0 0 0.5 0 -0 0</pose>
        <mass>1</mass>
        <inertia>
          <ixx>1</ixx>
          <ixy>0</ixy>
          <ixz>0</ixz>
          <iyy>1</iyy>
          <iyz>0</iyz>
          <izz>1</izz>
        </inertia>
      </inertial>
      <visual name='link_1'>
        <pose>0 0 0.5 0 -0 0</pose>
        <geometry>
          <box>
            <size>0.1 0.2 1</size>
          </box>
        </geometry>
      </visual>
    </link>

    <joint name='joint2' type='revolute'>
      <pose relative_to='link_1'>0 0 1 1.25 -0 0</pose>
      <parent>link_1</parent>
      <child>link_2</child>
      <axis>
        <xyz>1 0 0</xyz>
      </axis>
    </joint>
    <link name='link_2'>
      <pose relative_to='joint2'>0 0 0 0 -0 0</pose>
      <inertial>
        <pose>0 0 1 0 -0 0</pose>
        <mass>1</mass>
        <inertia>
          <ixx>1</ixx>
          <ixy>0</ixy>
          <ixz>0</ixz>
          <iyy>1</iyy>
          <iyz>0</iyz>
          <izz>1</izz>
        </inertia>
      </inertial>

      <visual name='link_2_visual'>
        <pose>0 0 2 0 -0 0</pose>
        <geometry>
          <box>
            <size>0.1 0.2 4</size>
          </box>
        </geometry>
      </visual>
    </link>

    <joint name='joint3' type='revolute'>
      <pose relative_to='link_2'>0 0 4 1.38 0 0</pose>
      <parent>link_2</parent>
      <child>link_box</child>
      <axis>
        <xyz>1 0 0</xyz>
      </axis>
    </joint>
    <link name='link_box'>
      <pose relative_to='joint3'>0 0 0 0 -0 0</pose>
      <inertial>
        <pose>0 0 0 0 -0 0</pose>
        <mass>1</mass>
        <inertia>
          <ixx>0.270</ixx>
          <ixy>0</ixy>
          <ixz>0</ixz>
          <iyy>0.270</iyy>
          <iyz>0</iyz>
          <izz>0.270</izz>
        </inertia>
      </inertial>
      <visual name='link_box_visual'>
        <pose>0 0 0 0 -0 0</pose>
        <geometry>
          <box>
            <size>0.5 0.5 0.5</size>
          </box>
        </geometry>
      </visual>
    </link>

    <joint name='linkboxfixed' type='fixed'>
      <pose relative_to='link_box'>0 0 0.25 0 -0 0</pose>
      <parent>link_box</parent>
      <child>ground</child>
    </joint>
    <link name='ground'>
      <pose relative_to='linkboxfixed'>0 0 0 0 -0 0</pose>
      <inertial>
        <pose>0 0 0 0 -0 0</pose>
        <mass>1</mass>
        <inertia>
          <ixx>1</ixx>
          <ixy>0</ixy>
          <ixz>0</ixz>
          <iyy>1</iyy>
          <iyz>0</iyz>
          <izz>1</izz>
        </inertia>
      </inertial>
      <visual name='ground_visual'>
        <pose>0 0 0.05 0 0 0</pose>
        <geometry>
          <box>
            <size>1 1 0.1</size>
          </box>
        </geometry>
      </visual>
    </link>

  </model>
</sdf>
